2019-12-01 13:54:33,434 ERROR: Exception on /search [GET] [in d:\projects\microblog\myenv\lib\site-packages\flask\app.py:1890]
Traceback (most recent call last):
  File "d:\projects\microblog\myenv\lib\site-packages\urllib3\connection.py", line 156, in _new_conn
    conn = connection.create_connection(
  File "d:\projects\microblog\myenv\lib\site-packages\urllib3\util\connection.py", line 84, in create_connection
    raise err
  File "d:\projects\microblog\myenv\lib\site-packages\urllib3\util\connection.py", line 74, in create_connection
    sock.connect(sa)
ConnectionRefusedError: [WinError 10061] No connection could be made because the target machine actively refused it

During handling of the above exception, another exception occurred:

Traceback (most recent call last):
  File "d:\projects\microblog\myenv\lib\site-packages\elasticsearch\connection\http_urllib3.py", line 237, in perform_request
    response = self.pool.urlopen(
  File "d:\projects\microblog\myenv\lib\site-packages\urllib3\connectionpool.py", line 719, in urlopen
    retries = retries.increment(
  File "d:\projects\microblog\myenv\lib\site-packages\urllib3\util\retry.py", line 376, in increment
    raise six.reraise(type(error), error, _stacktrace)
  File "d:\projects\microblog\myenv\lib\site-packages\urllib3\packages\six.py", line 735, in reraise
    raise value
  File "d:\projects\microblog\myenv\lib\site-packages\urllib3\connectionpool.py", line 665, in urlopen
    httplib_response = self._make_request(
  File "d:\projects\microblog\myenv\lib\site-packages\urllib3\connectionpool.py", line 387, in _make_request
    conn.request(method, url, **httplib_request_kw)
  File "C:\Users\swapn\AppData\Local\Programs\Python\Python38\lib\http\client.py", line 1230, in request
    self._send_request(method, url, body, headers, encode_chunked)
  File "C:\Users\swapn\AppData\Local\Programs\Python\Python38\lib\http\client.py", line 1276, in _send_request
    self.endheaders(body, encode_chunked=encode_chunked)
  File "C:\Users\swapn\AppData\Local\Programs\Python\Python38\lib\http\client.py", line 1225, in endheaders
    self._send_output(message_body, encode_chunked=encode_chunked)
  File "C:\Users\swapn\AppData\Local\Programs\Python\Python38\lib\http\client.py", line 1004, in _send_output
    self.send(msg)
  File "C:\Users\swapn\AppData\Local\Programs\Python\Python38\lib\http\client.py", line 944, in send
    self.connect()
  File "d:\projects\microblog\myenv\lib\site-packages\urllib3\connection.py", line 184, in connect
    conn = self._new_conn()
  File "d:\projects\microblog\myenv\lib\site-packages\urllib3\connection.py", line 168, in _new_conn
    raise NewConnectionError(
urllib3.exceptions.NewConnectionError: <urllib3.connection.HTTPConnection object at 0x0000023A2D93CA60>: Failed to establish a new connection: [WinError 10061] No connection could be made because the target machine actively refused it

During handling of the above exception, another exception occurred:

Traceback (most recent call last):
  File "d:\projects\microblog\myenv\lib\site-packages\flask\app.py", line 2446, in wsgi_app
    response = self.full_dispatch_request()
  File "d:\projects\microblog\myenv\lib\site-packages\flask\app.py", line 1951, in full_dispatch_request
    rv = self.handle_user_exception(e)
  File "d:\projects\microblog\myenv\lib\site-packages\flask\app.py", line 1820, in handle_user_exception
    reraise(exc_type, exc_value, tb)
  File "d:\projects\microblog\myenv\lib\site-packages\flask\_compat.py", line 39, in reraise
    raise value
  File "d:\projects\microblog\myenv\lib\site-packages\flask\app.py", line 1949, in full_dispatch_request
    rv = self.dispatch_request()
  File "d:\projects\microblog\myenv\lib\site-packages\flask\app.py", line 1935, in dispatch_request
    return self.view_functions[rule.endpoint](**req.view_args)
  File "d:\projects\microblog\myenv\lib\site-packages\flask_login\utils.py", line 261, in decorated_view
    return func(*args, **kwargs)
  File "D:\projects\microblog\app\main\routes.py", line 143, in search
    posts, total = Post.search(g.search_form.q.data, page,
  File "D:\projects\microblog\app\models.py", line 15, in search
    ids, total = query_index(cls.__tablename__, expression, page, per_page)
  File "D:\projects\microblog\app\search.py", line 22, in query_index
    search = current_app.elasticsearch.search(
  File "d:\projects\microblog\myenv\lib\site-packages\elasticsearch\client\utils.py", line 84, in _wrapped
    return func(*args, params=params, **kwargs)
  File "d:\projects\microblog\myenv\lib\site-packages\elasticsearch\client\__init__.py", line 810, in search
    return self.transport.perform_request(
  File "d:\projects\microblog\myenv\lib\site-packages\elasticsearch\transport.py", line 351, in perform_request
    status, headers_response, data = connection.perform_request(
  File "d:\projects\microblog\myenv\lib\site-packages\elasticsearch\connection\http_urllib3.py", line 250, in perform_request
    raise ConnectionError("N/A", str(e), e)
elasticsearch.exceptions.ConnectionError: ConnectionError(<urllib3.connection.HTTPConnection object at 0x0000023A2D93CA60>: Failed to establish a new connection: [WinError 10061] No connection could be made because the target machine actively refused it) caused by: NewConnectionError(<urllib3.connection.HTTPConnection object at 0x0000023A2D93CA60>: Failed to establish a new connection: [WinError 10061] No connection could be made because the target machine actively refused it)
2019-12-01 13:56:41,285 ERROR: Exception on /search [GET] [in d:\projects\microblog\myenv\lib\site-packages\flask\app.py:1890]
Traceback (most recent call last):
  File "d:\projects\microblog\myenv\lib\site-packages\flask\app.py", line 2446, in wsgi_app
    response = self.full_dispatch_request()
  File "d:\projects\microblog\myenv\lib\site-packages\flask\app.py", line 1951, in full_dispatch_request
    rv = self.handle_user_exception(e)
  File "d:\projects\microblog\myenv\lib\site-packages\flask\app.py", line 1820, in handle_user_exception
    reraise(exc_type, exc_value, tb)
  File "d:\projects\microblog\myenv\lib\site-packages\flask\_compat.py", line 39, in reraise
    raise value
  File "d:\projects\microblog\myenv\lib\site-packages\flask\app.py", line 1949, in full_dispatch_request
    rv = self.dispatch_request()
  File "d:\projects\microblog\myenv\lib\site-packages\flask\app.py", line 1935, in dispatch_request
    return self.view_functions[rule.endpoint](**req.view_args)
  File "d:\projects\microblog\myenv\lib\site-packages\flask_login\utils.py", line 261, in decorated_view
    return func(*args, **kwargs)
  File "D:\projects\microblog\app\main\routes.py", line 143, in search
    posts, total = Post.search(g.search_form.q.data, page,
  File "D:\projects\microblog\app\models.py", line 15, in search
    ids, total = query_index(cls.__tablename__, expression, page, per_page)
  File "D:\projects\microblog\app\search.py", line 22, in query_index
    search = current_app.elasticsearch.search(
  File "d:\projects\microblog\myenv\lib\site-packages\elasticsearch\client\utils.py", line 84, in _wrapped
    return func(*args, params=params, **kwargs)
  File "d:\projects\microblog\myenv\lib\site-packages\elasticsearch\client\__init__.py", line 810, in search
    return self.transport.perform_request(
  File "d:\projects\microblog\myenv\lib\site-packages\elasticsearch\transport.py", line 351, in perform_request
    status, headers_response, data = connection.perform_request(
  File "d:\projects\microblog\myenv\lib\site-packages\elasticsearch\connection\http_urllib3.py", line 257, in perform_request
    self._raise_error(response.status, raw_data)
  File "d:\projects\microblog\myenv\lib\site-packages\elasticsearch\connection\base.py", line 181, in _raise_error
    raise HTTP_EXCEPTIONS.get(status_code, TransportError)(
elasticsearch.exceptions.NotFoundError: NotFoundError(404, 'index_not_found_exception', 'no such index [post]', post, index_or_alias)
2019-12-01 14:07:41,524 INFO: Microblog startup [in D:\projects\microblog\app\__init__.py:77]
