2019-12-03 14:06:03,368 ERROR: Exception on /index [POST] [in /home/swapnil/projects/microblog/myenv/lib/python3.6/site-packages/flask/app.py:1891]
Traceback (most recent call last):
  File "/home/swapnil/projects/microblog/myenv/lib/python3.6/site-packages/urllib3/connection.py", line 157, in _new_conn
    (self._dns_host, self.port), self.timeout, **extra_kw
  File "/home/swapnil/projects/microblog/myenv/lib/python3.6/site-packages/urllib3/util/connection.py", line 84, in create_connection
    raise err
  File "/home/swapnil/projects/microblog/myenv/lib/python3.6/site-packages/urllib3/util/connection.py", line 74, in create_connection
    sock.connect(sa)
ConnectionRefusedError: [Errno 111] Connection refused

During handling of the above exception, another exception occurred:

Traceback (most recent call last):
  File "/home/swapnil/projects/microblog/myenv/lib/python3.6/site-packages/elasticsearch/connection/http_urllib3.py", line 238, in perform_request
    method, url, body, retries=Retry(False), headers=request_headers, **kw
  File "/home/swapnil/projects/microblog/myenv/lib/python3.6/site-packages/urllib3/connectionpool.py", line 720, in urlopen
    method, url, error=e, _pool=self, _stacktrace=sys.exc_info()[2]
  File "/home/swapnil/projects/microblog/myenv/lib/python3.6/site-packages/urllib3/util/retry.py", line 376, in increment
    raise six.reraise(type(error), error, _stacktrace)
  File "/home/swapnil/projects/microblog/myenv/lib/python3.6/site-packages/urllib3/packages/six.py", line 735, in reraise
    raise value
  File "/home/swapnil/projects/microblog/myenv/lib/python3.6/site-packages/urllib3/connectionpool.py", line 672, in urlopen
    chunked=chunked,
  File "/home/swapnil/projects/microblog/myenv/lib/python3.6/site-packages/urllib3/connectionpool.py", line 387, in _make_request
    conn.request(method, url, **httplib_request_kw)
  File "/usr/lib/python3.6/http/client.py", line 1254, in request
    self._send_request(method, url, body, headers, encode_chunked)
  File "/usr/lib/python3.6/http/client.py", line 1300, in _send_request
    self.endheaders(body, encode_chunked=encode_chunked)
  File "/usr/lib/python3.6/http/client.py", line 1249, in endheaders
    self._send_output(message_body, encode_chunked=encode_chunked)
  File "/usr/lib/python3.6/http/client.py", line 1036, in _send_output
    self.send(msg)
  File "/usr/lib/python3.6/http/client.py", line 974, in send
    self.connect()
  File "/home/swapnil/projects/microblog/myenv/lib/python3.6/site-packages/urllib3/connection.py", line 184, in connect
    conn = self._new_conn()
  File "/home/swapnil/projects/microblog/myenv/lib/python3.6/site-packages/urllib3/connection.py", line 169, in _new_conn
    self, "Failed to establish a new connection: %s" % e
urllib3.exceptions.NewConnectionError: <urllib3.connection.HTTPConnection object at 0x7f3592aff080>: Failed to establish a new connection: [Errno 111] Connection refused

During handling of the above exception, another exception occurred:

Traceback (most recent call last):
  File "/home/swapnil/projects/microblog/myenv/lib/python3.6/site-packages/flask/app.py", line 2446, in wsgi_app
    response = self.full_dispatch_request()
  File "/home/swapnil/projects/microblog/myenv/lib/python3.6/site-packages/flask/app.py", line 1951, in full_dispatch_request
    rv = self.handle_user_exception(e)
  File "/home/swapnil/projects/microblog/myenv/lib/python3.6/site-packages/flask/app.py", line 1820, in handle_user_exception
    reraise(exc_type, exc_value, tb)
  File "/home/swapnil/projects/microblog/myenv/lib/python3.6/site-packages/flask/_compat.py", line 39, in reraise
    raise value
  File "/home/swapnil/projects/microblog/myenv/lib/python3.6/site-packages/flask/app.py", line 1949, in full_dispatch_request
    rv = self.dispatch_request()
  File "/home/swapnil/projects/microblog/myenv/lib/python3.6/site-packages/flask/app.py", line 1935, in dispatch_request
    return self.view_functions[rule.endpoint](**req.view_args)
  File "/home/swapnil/projects/microblog/myenv/lib/python3.6/site-packages/flask_login/utils.py", line 261, in decorated_view
    return func(*args, **kwargs)
  File "/home/swapnil/projects/microblog/app/main/routes.py", line 35, in index
    db.session.commit()
  File "/home/swapnil/projects/microblog/myenv/lib/python3.6/site-packages/sqlalchemy/orm/scoping.py", line 162, in do
    return getattr(self.registry(), name)(*args, **kwargs)
  File "/home/swapnil/projects/microblog/myenv/lib/python3.6/site-packages/sqlalchemy/orm/session.py", line 1027, in commit
    self.transaction.commit()
  File "/home/swapnil/projects/microblog/myenv/lib/python3.6/site-packages/sqlalchemy/orm/session.py", line 501, in commit
    self.session.dispatch.after_commit(self.session)
  File "/home/swapnil/projects/microblog/myenv/lib/python3.6/site-packages/sqlalchemy/event/attr.py", line 261, in __call__
    fn(*args, **kw)
  File "/home/swapnil/projects/microblog/app/models.py", line 39, in after_commit
    add_to_index(obj.__tablename__, obj)
  File "/home/swapnil/projects/microblog/app/search.py", line 10, in add_to_index
    current_app.elasticsearch.index(index=index, id=model.id, body=payload)
  File "/home/swapnil/projects/microblog/myenv/lib/python3.6/site-packages/elasticsearch/client/utils.py", line 84, in _wrapped
    return func(*args, params=params, **kwargs)
  File "/home/swapnil/projects/microblog/myenv/lib/python3.6/site-packages/elasticsearch/client/__init__.py", line 370, in index
    "POST", _make_path(index, doc_type, id), params=params, body=body
  File "/home/swapnil/projects/microblog/myenv/lib/python3.6/site-packages/elasticsearch/transport.py", line 358, in perform_request
    timeout=timeout,
  File "/home/swapnil/projects/microblog/myenv/lib/python3.6/site-packages/elasticsearch/connection/http_urllib3.py", line 250, in perform_request
    raise ConnectionError("N/A", str(e), e)
elasticsearch.exceptions.ConnectionError: ConnectionError(<urllib3.connection.HTTPConnection object at 0x7f3592aff080>: Failed to establish a new connection: [Errno 111] Connection refused) caused by: NewConnectionError(<urllib3.connection.HTTPConnection object at 0x7f3592aff080>: Failed to establish a new connection: [Errno 111] Connection refused)
2019-12-03 14:06:26,737 INFO: Microblog startup [in ./app/__init__.py:81]
2019-12-03 14:08:32,885 INFO: Microblog startup [in /home/swapnil/projects/microblog/app/__init__.py:81]
2019-12-03 14:08:40,728 INFO: Microblog startup [in /home/swapnil/projects/microblog/app/__init__.py:81]
2019-12-03 14:08:46,216 INFO: Microblog startup [in /home/swapnil/projects/microblog/app/__init__.py:81]
2019-12-03 14:54:59,567 INFO: Microblog startup [in /home/swapnil/projects/microblog/app/__init__.py:86]
2019-12-03 20:58:13,372 INFO: Microblog startup [in /home/swapnil/projects/microblog/app/__init__.py:89]
2019-12-03 20:58:32,436 INFO: Microblog startup [in /home/swapnil/projects/microblog/app/__init__.py:89]
2019-12-03 20:58:41,034 INFO: Microblog startup [in /home/swapnil/projects/microblog/app/__init__.py:89]
2019-12-03 21:00:49,628 INFO: Microblog startup [in /home/swapnil/projects/microblog/app/__init__.py:89]
